2025-07-21 16:41:19,372 - main - INFO - Starting up FastAPI Recruitment Platform...
2025-07-21 16:41:19,650 - app.core.database - INFO - Database tables created successfully
2025-07-21 16:41:19,650 - main - INFO - Database initialized successfully
2025-07-21 16:43:49,662 - main - INFO - Shutting down FastAPI Recruitment Platform...
2025-07-21 16:43:50,487 - main - INFO - Starting up FastAPI Recruitment Platform...
2025-07-21 16:43:50,517 - app.core.database - INFO - Database tables created successfully
2025-07-21 16:43:50,517 - main - INFO - Database initialized successfully
2025-07-21 16:43:53,694 - app.core.database - ERROR - Database session error: 1 validation error for UserResponse
updated_at
  Error extracting attribute: MissingGreenlet: greenlet_spawn has not been called; can't call await_only() here. Was IO attempted in an unexpected place? (Background on this error at: https://sqlalche.me/e/20/xd2s) [type=get_attribute_error, input_value=<unprintable User object>, input_type=User]
    For further information visit https://errors.pydantic.dev/2.11/v/get_attribute_error
2025-07-21 16:43:53,694 - main - ERROR - Unhandled exception: 1 validation error for UserResponse
updated_at
  Error extracting attribute: MissingGreenlet: greenlet_spawn has not been called; can't call await_only() here. Was IO attempted in an unexpected place? (Background on this error at: https://sqlalche.me/e/20/xd2s) [type=get_attribute_error, input_value=<unprintable User object>, input_type=User]
    For further information visit https://errors.pydantic.dev/2.11/v/get_attribute_error
Traceback (most recent call last):
  File "/openhands/poetry/openhands-ai-5O4_aCHf-py3.12/lib/python3.12/site-packages/starlette/middleware/errors.py", line 165, in __call__
    await self.app(scope, receive, _send)
  File "/openhands/poetry/openhands-ai-5O4_aCHf-py3.12/lib/python3.12/site-packages/starlette/middleware/cors.py", line 85, in __call__
    await self.app(scope, receive, send)
  File "/openhands/poetry/openhands-ai-5O4_aCHf-py3.12/lib/python3.12/site-packages/starlette/middleware/exceptions.py", line 62, in __call__
    await wrap_app_handling_exceptions(self.app, conn)(scope, receive, send)
  File "/openhands/poetry/openhands-ai-5O4_aCHf-py3.12/lib/python3.12/site-packages/starlette/_exception_handler.py", line 53, in wrapped_app
    raise exc
  File "/openhands/poetry/openhands-ai-5O4_aCHf-py3.12/lib/python3.12/site-packages/starlette/_exception_handler.py", line 42, in wrapped_app
    await app(scope, receive, sender)
  File "/openhands/poetry/openhands-ai-5O4_aCHf-py3.12/lib/python3.12/site-packages/starlette/routing.py", line 714, in __call__
    await self.middleware_stack(scope, receive, send)
  File "/openhands/poetry/openhands-ai-5O4_aCHf-py3.12/lib/python3.12/site-packages/starlette/routing.py", line 734, in app
    await route.handle(scope, receive, send)
  File "/openhands/poetry/openhands-ai-5O4_aCHf-py3.12/lib/python3.12/site-packages/starlette/routing.py", line 288, in handle
    await self.app(scope, receive, send)
  File "/openhands/poetry/openhands-ai-5O4_aCHf-py3.12/lib/python3.12/site-packages/starlette/routing.py", line 76, in app
    await wrap_app_handling_exceptions(app, request)(scope, receive, send)
  File "/openhands/poetry/openhands-ai-5O4_aCHf-py3.12/lib/python3.12/site-packages/starlette/_exception_handler.py", line 53, in wrapped_app
    raise exc
  File "/openhands/poetry/openhands-ai-5O4_aCHf-py3.12/lib/python3.12/site-packages/starlette/_exception_handler.py", line 42, in wrapped_app
    await app(scope, receive, sender)
  File "/openhands/poetry/openhands-ai-5O4_aCHf-py3.12/lib/python3.12/site-packages/starlette/routing.py", line 73, in app
    response = await f(request)
               ^^^^^^^^^^^^^^^^
  File "/openhands/poetry/openhands-ai-5O4_aCHf-py3.12/lib/python3.12/site-packages/fastapi/routing.py", line 301, in app
    raw_response = await run_endpoint_function(
                   ^^^^^^^^^^^^^^^^^^^^^^^^^^^^
  File "/openhands/poetry/openhands-ai-5O4_aCHf-py3.12/lib/python3.12/site-packages/fastapi/routing.py", line 212, in run_endpoint_function
    return await dependant.call(**values)
           ^^^^^^^^^^^^^^^^^^^^^^^^^^^^^^
  File "/workspace/Hire-quick/fastapi_app/app/api/v1/endpoints/auth.py", line 152, in login
    user=UserResponse.from_orm(user)
         ^^^^^^^^^^^^^^^^^^^^^^^^^^^
  File "/openhands/poetry/openhands-ai-5O4_aCHf-py3.12/lib/python3.12/site-packages/pydantic/main.py", line 1440, in from_orm
    return cls.model_validate(obj)
           ^^^^^^^^^^^^^^^^^^^^^^^
  File "/openhands/poetry/openhands-ai-5O4_aCHf-py3.12/lib/python3.12/site-packages/pydantic/main.py", line 705, in model_validate
    return cls.__pydantic_validator__.validate_python(
           ^^^^^^^^^^^^^^^^^^^^^^^^^^^^^^^^^^^^^^^^^^^
pydantic_core._pydantic_core.ValidationError: 1 validation error for UserResponse
updated_at
  Error extracting attribute: MissingGreenlet: greenlet_spawn has not been called; can't call await_only() here. Was IO attempted in an unexpected place? (Background on this error at: https://sqlalche.me/e/20/xd2s) [type=get_attribute_error, input_value=<unprintable User object>, input_type=User]
    For further information visit https://errors.pydantic.dev/2.11/v/get_attribute_error
2025-07-21 16:44:18,345 - main - INFO - Shutting down FastAPI Recruitment Platform...
2025-07-21 16:44:19,150 - main - INFO - Starting up FastAPI Recruitment Platform...
2025-07-21 16:44:19,181 - app.core.database - INFO - Database tables created successfully
2025-07-21 16:44:19,182 - main - INFO - Database initialized successfully
2025-07-21 16:44:23,793 - main - INFO - Shutting down FastAPI Recruitment Platform...
2025-07-21 16:44:24,582 - main - INFO - Starting up FastAPI Recruitment Platform...
2025-07-21 16:44:24,617 - app.core.database - INFO - Database tables created successfully
2025-07-21 16:44:24,617 - main - INFO - Database initialized successfully
2025-07-21 16:44:29,729 - main - INFO - Shutting down FastAPI Recruitment Platform...
2025-07-21 16:44:30,602 - main - INFO - Starting up FastAPI Recruitment Platform...
2025-07-21 16:44:30,633 - app.core.database - INFO - Database tables created successfully
2025-07-21 16:44:30,633 - main - INFO - Database initialized successfully
2025-07-21 16:44:35,746 - main - INFO - Shutting down FastAPI Recruitment Platform...
2025-07-21 16:44:36,709 - main - INFO - Starting up FastAPI Recruitment Platform...
2025-07-21 16:44:36,739 - app.core.database - INFO - Database tables created successfully
2025-07-21 16:44:36,739 - main - INFO - Database initialized successfully
2025-07-21 16:44:43,254 - main - INFO - Shutting down FastAPI Recruitment Platform...
2025-07-21 16:44:44,055 - main - INFO - Starting up FastAPI Recruitment Platform...
2025-07-21 16:44:44,085 - app.core.database - INFO - Database tables created successfully
2025-07-21 16:44:44,085 - main - INFO - Database initialized successfully
2025-07-21 16:44:47,882 - app.core.database - ERROR - Database session error: User with this email already exists
2025-07-21 16:44:47,882 - main - ERROR - Unhandled exception: User with this email already exists
Traceback (most recent call last):
  File "/openhands/poetry/openhands-ai-5O4_aCHf-py3.12/lib/python3.12/site-packages/starlette/middleware/errors.py", line 165, in __call__
    await self.app(scope, receive, _send)
  File "/openhands/poetry/openhands-ai-5O4_aCHf-py3.12/lib/python3.12/site-packages/starlette/middleware/cors.py", line 85, in __call__
    await self.app(scope, receive, send)
  File "/openhands/poetry/openhands-ai-5O4_aCHf-py3.12/lib/python3.12/site-packages/starlette/middleware/exceptions.py", line 62, in __call__
    await wrap_app_handling_exceptions(self.app, conn)(scope, receive, send)
  File "/openhands/poetry/openhands-ai-5O4_aCHf-py3.12/lib/python3.12/site-packages/starlette/_exception_handler.py", line 53, in wrapped_app
    raise exc
  File "/openhands/poetry/openhands-ai-5O4_aCHf-py3.12/lib/python3.12/site-packages/starlette/_exception_handler.py", line 42, in wrapped_app
    await app(scope, receive, sender)
  File "/openhands/poetry/openhands-ai-5O4_aCHf-py3.12/lib/python3.12/site-packages/starlette/routing.py", line 714, in __call__
    await self.middleware_stack(scope, receive, send)
  File "/openhands/poetry/openhands-ai-5O4_aCHf-py3.12/lib/python3.12/site-packages/starlette/routing.py", line 734, in app
    await route.handle(scope, receive, send)
  File "/openhands/poetry/openhands-ai-5O4_aCHf-py3.12/lib/python3.12/site-packages/starlette/routing.py", line 288, in handle
    await self.app(scope, receive, send)
  File "/openhands/poetry/openhands-ai-5O4_aCHf-py3.12/lib/python3.12/site-packages/starlette/routing.py", line 76, in app
    await wrap_app_handling_exceptions(app, request)(scope, receive, send)
  File "/openhands/poetry/openhands-ai-5O4_aCHf-py3.12/lib/python3.12/site-packages/starlette/_exception_handler.py", line 53, in wrapped_app
    raise exc
  File "/openhands/poetry/openhands-ai-5O4_aCHf-py3.12/lib/python3.12/site-packages/starlette/_exception_handler.py", line 42, in wrapped_app
    await app(scope, receive, sender)
  File "/openhands/poetry/openhands-ai-5O4_aCHf-py3.12/lib/python3.12/site-packages/starlette/routing.py", line 73, in app
    response = await f(request)
               ^^^^^^^^^^^^^^^^
  File "/openhands/poetry/openhands-ai-5O4_aCHf-py3.12/lib/python3.12/site-packages/fastapi/routing.py", line 301, in app
    raw_response = await run_endpoint_function(
                   ^^^^^^^^^^^^^^^^^^^^^^^^^^^^
  File "/openhands/poetry/openhands-ai-5O4_aCHf-py3.12/lib/python3.12/site-packages/fastapi/routing.py", line 212, in run_endpoint_function
    return await dependant.call(**values)
           ^^^^^^^^^^^^^^^^^^^^^^^^^^^^^^
  File "/workspace/Hire-quick/fastapi_app/app/api/v1/endpoints/auth.py", line 69, in register
    raise ConflictException("User with this email already exists")
app.core.exceptions.ConflictException: User with this email already exists
2025-07-21 16:44:56,084 - main - INFO - Shutting down FastAPI Recruitment Platform...
2025-07-21 16:44:56,891 - main - INFO - Starting up FastAPI Recruitment Platform...
2025-07-21 16:44:56,920 - app.core.database - INFO - Database tables created successfully
2025-07-21 16:44:56,920 - main - INFO - Database initialized successfully
2025-07-21 16:45:00,830 - main - INFO - Shutting down FastAPI Recruitment Platform...
2025-07-21 16:45:01,618 - main - INFO - Starting up FastAPI Recruitment Platform...
2025-07-21 16:45:01,647 - app.core.database - INFO - Database tables created successfully
2025-07-21 16:45:01,647 - main - INFO - Database initialized successfully
2025-07-21 16:45:05,557 - main - INFO - Shutting down FastAPI Recruitment Platform...
2025-07-21 16:45:06,358 - main - INFO - Starting up FastAPI Recruitment Platform...
2025-07-21 16:45:06,389 - app.core.database - INFO - Database tables created successfully
2025-07-21 16:45:06,389 - main - INFO - Database initialized successfully
2025-07-21 16:45:12,178 - app.core.database - ERROR - Database session error: greenlet_spawn has not been called; can't call await_only() here. Was IO attempted in an unexpected place? (Background on this error at: https://sqlalche.me/e/20/xd2s)
2025-07-21 16:45:12,179 - main - ERROR - Unhandled exception: greenlet_spawn has not been called; can't call await_only() here. Was IO attempted in an unexpected place? (Background on this error at: https://sqlalche.me/e/20/xd2s)
Traceback (most recent call last):
  File "/openhands/poetry/openhands-ai-5O4_aCHf-py3.12/lib/python3.12/site-packages/starlette/middleware/errors.py", line 165, in __call__
    await self.app(scope, receive, _send)
  File "/openhands/poetry/openhands-ai-5O4_aCHf-py3.12/lib/python3.12/site-packages/starlette/middleware/cors.py", line 85, in __call__
    await self.app(scope, receive, send)
  File "/openhands/poetry/openhands-ai-5O4_aCHf-py3.12/lib/python3.12/site-packages/starlette/middleware/exceptions.py", line 62, in __call__
    await wrap_app_handling_exceptions(self.app, conn)(scope, receive, send)
  File "/openhands/poetry/openhands-ai-5O4_aCHf-py3.12/lib/python3.12/site-packages/starlette/_exception_handler.py", line 53, in wrapped_app
    raise exc
  File "/openhands/poetry/openhands-ai-5O4_aCHf-py3.12/lib/python3.12/site-packages/starlette/_exception_handler.py", line 42, in wrapped_app
    await app(scope, receive, sender)
  File "/openhands/poetry/openhands-ai-5O4_aCHf-py3.12/lib/python3.12/site-packages/starlette/routing.py", line 714, in __call__
    await self.middleware_stack(scope, receive, send)
  File "/openhands/poetry/openhands-ai-5O4_aCHf-py3.12/lib/python3.12/site-packages/starlette/routing.py", line 734, in app
    await route.handle(scope, receive, send)
  File "/openhands/poetry/openhands-ai-5O4_aCHf-py3.12/lib/python3.12/site-packages/starlette/routing.py", line 288, in handle
    await self.app(scope, receive, send)
  File "/openhands/poetry/openhands-ai-5O4_aCHf-py3.12/lib/python3.12/site-packages/starlette/routing.py", line 76, in app
    await wrap_app_handling_exceptions(app, request)(scope, receive, send)
  File "/openhands/poetry/openhands-ai-5O4_aCHf-py3.12/lib/python3.12/site-packages/starlette/_exception_handler.py", line 53, in wrapped_app
    raise exc
  File "/openhands/poetry/openhands-ai-5O4_aCHf-py3.12/lib/python3.12/site-packages/starlette/_exception_handler.py", line 42, in wrapped_app
    await app(scope, receive, sender)
  File "/openhands/poetry/openhands-ai-5O4_aCHf-py3.12/lib/python3.12/site-packages/starlette/routing.py", line 73, in app
    response = await f(request)
               ^^^^^^^^^^^^^^^^
  File "/openhands/poetry/openhands-ai-5O4_aCHf-py3.12/lib/python3.12/site-packages/fastapi/routing.py", line 301, in app
    raw_response = await run_endpoint_function(
                   ^^^^^^^^^^^^^^^^^^^^^^^^^^^^
  File "/openhands/poetry/openhands-ai-5O4_aCHf-py3.12/lib/python3.12/site-packages/fastapi/routing.py", line 212, in run_endpoint_function
    return await dependant.call(**values)
           ^^^^^^^^^^^^^^^^^^^^^^^^^^^^^^
  File "/workspace/Hire-quick/fastapi_app/app/api/v1/endpoints/auth.py", line 173, in login
    "updated_at": user.updated_at,
                  ^^^^^^^^^^^^^^^
  File "/openhands/poetry/openhands-ai-5O4_aCHf-py3.12/lib/python3.12/site-packages/sqlalchemy/orm/attributes.py", line 566, in __get__
    return self.impl.get(state, dict_)  # type: ignore[no-any-return]
           ^^^^^^^^^^^^^^^^^^^^^^^^^^^
  File "/openhands/poetry/openhands-ai-5O4_aCHf-py3.12/lib/python3.12/site-packages/sqlalchemy/orm/attributes.py", line 1086, in get
    value = self._fire_loader_callables(state, key, passive)
            ^^^^^^^^^^^^^^^^^^^^^^^^^^^^^^^^^^^^^^^^^^^^^^^^
  File "/openhands/poetry/openhands-ai-5O4_aCHf-py3.12/lib/python3.12/site-packages/sqlalchemy/orm/attributes.py", line 1116, in _fire_loader_callables
    return state._load_expired(state, passive)
           ^^^^^^^^^^^^^^^^^^^^^^^^^^^^^^^^^^^
  File "/openhands/poetry/openhands-ai-5O4_aCHf-py3.12/lib/python3.12/site-packages/sqlalchemy/orm/state.py", line 803, in _load_expired
    self.manager.expired_attribute_loader(self, toload, passive)
  File "/openhands/poetry/openhands-ai-5O4_aCHf-py3.12/lib/python3.12/site-packages/sqlalchemy/orm/loading.py", line 1670, in load_scalar_attributes
    result = load_on_ident(
             ^^^^^^^^^^^^^^
  File "/openhands/poetry/openhands-ai-5O4_aCHf-py3.12/lib/python3.12/site-packages/sqlalchemy/orm/loading.py", line 509, in load_on_ident
    return load_on_pk_identity(
           ^^^^^^^^^^^^^^^^^^^^
  File "/openhands/poetry/openhands-ai-5O4_aCHf-py3.12/lib/python3.12/site-packages/sqlalchemy/orm/loading.py", line 694, in load_on_pk_identity
    session.execute(
  File "/openhands/poetry/openhands-ai-5O4_aCHf-py3.12/lib/python3.12/site-packages/sqlalchemy/orm/session.py", line 2365, in execute
    return self._execute_internal(
           ^^^^^^^^^^^^^^^^^^^^^^^
  File "/openhands/poetry/openhands-ai-5O4_aCHf-py3.12/lib/python3.12/site-packages/sqlalchemy/orm/session.py", line 2251, in _execute_internal
    result: Result[Any] = compile_state_cls.orm_execute_statement(
                          ^^^^^^^^^^^^^^^^^^^^^^^^^^^^^^^^^^^^^^^^
  File "/openhands/poetry/openhands-ai-5O4_aCHf-py3.12/lib/python3.12/site-packages/sqlalchemy/orm/context.py", line 306, in orm_execute_statement
    result = conn.execute(
             ^^^^^^^^^^^^^
  File "/openhands/poetry/openhands-ai-5O4_aCHf-py3.12/lib/python3.12/site-packages/sqlalchemy/engine/base.py", line 1415, in execute
    return meth(
           ^^^^^
  File "/openhands/poetry/openhands-ai-5O4_aCHf-py3.12/lib/python3.12/site-packages/sqlalchemy/sql/elements.py", line 523, in _execute_on_connection
    return connection._execute_clauseelement(
           ^^^^^^^^^^^^^^^^^^^^^^^^^^^^^^^^^^
  File "/openhands/poetry/openhands-ai-5O4_aCHf-py3.12/lib/python3.12/site-packages/sqlalchemy/engine/base.py", line 1637, in _execute_clauseelement
    ret = self._execute_context(
          ^^^^^^^^^^^^^^^^^^^^^^
  File "/openhands/poetry/openhands-ai-5O4_aCHf-py3.12/lib/python3.12/site-packages/sqlalchemy/engine/base.py", line 1842, in _execute_context
    return self._exec_single_context(
           ^^^^^^^^^^^^^^^^^^^^^^^^^^
  File "/openhands/poetry/openhands-ai-5O4_aCHf-py3.12/lib/python3.12/site-packages/sqlalchemy/engine/base.py", line 1982, in _exec_single_context
    self._handle_dbapi_exception(
  File "/openhands/poetry/openhands-ai-5O4_aCHf-py3.12/lib/python3.12/site-packages/sqlalchemy/engine/base.py", line 2354, in _handle_dbapi_exception
    raise exc_info[1].with_traceback(exc_info[2])
  File "/openhands/poetry/openhands-ai-5O4_aCHf-py3.12/lib/python3.12/site-packages/sqlalchemy/engine/base.py", line 1963, in _exec_single_context
    self.dialect.do_execute(
  File "/openhands/poetry/openhands-ai-5O4_aCHf-py3.12/lib/python3.12/site-packages/sqlalchemy/engine/default.py", line 943, in do_execute
    cursor.execute(statement, parameters)
  File "/openhands/poetry/openhands-ai-5O4_aCHf-py3.12/lib/python3.12/site-packages/sqlalchemy/dialects/sqlite/aiosqlite.py", line 149, in execute
    self._adapt_connection._handle_exception(error)
  File "/openhands/poetry/openhands-ai-5O4_aCHf-py3.12/lib/python3.12/site-packages/sqlalchemy/dialects/sqlite/aiosqlite.py", line 300, in _handle_exception
    raise error
  File "/openhands/poetry/openhands-ai-5O4_aCHf-py3.12/lib/python3.12/site-packages/sqlalchemy/dialects/sqlite/aiosqlite.py", line 126, in execute
    _cursor = self.await_(self._connection.cursor())
              ^^^^^^^^^^^^^^^^^^^^^^^^^^^^^^^^^^^^^^
  File "/openhands/poetry/openhands-ai-5O4_aCHf-py3.12/lib/python3.12/site-packages/sqlalchemy/util/_concurrency_py3k.py", line 123, in await_only
    raise exc.MissingGreenlet(
sqlalchemy.exc.MissingGreenlet: greenlet_spawn has not been called; can't call await_only() here. Was IO attempted in an unexpected place? (Background on this error at: https://sqlalche.me/e/20/xd2s)
2025-07-21 16:45:22,896 - main - INFO - Shutting down FastAPI Recruitment Platform...
2025-07-21 16:45:23,690 - main - INFO - Starting up FastAPI Recruitment Platform...
2025-07-21 16:45:23,724 - app.core.database - INFO - Database tables created successfully
2025-07-21 16:45:23,725 - main - INFO - Database initialized successfully
